~/workspace$ python - <<'PY'
import redis, json, time
r = redis.Redis(host='localhost', port=6379, decode_responses=True)
print("Ping:", r.ping())             # → True
# пробуем запись/чтение
r.setex("test_key", 60, "hello")
print("Stored:", r.get("test_key"))
PY
Traceback (most recent call last):
  File "/home/runner/workspace/.pythonlibs/lib/python3.11/site-packages/redis/connection.py", line 385, in connect_check_health
    sock = self.retry.call_with_retry(
           ^^^^^^^^^^^^^^^^^^^^^^^^^^^
  File "/home/runner/workspace/.pythonlibs/lib/python3.11/site-packages/redis/retry.py", line 87, in call_with_retry
    return do()
           ^^^^
  File "/home/runner/workspace/.pythonlibs/lib/python3.11/site-packages/redis/connection.py", line 386, in <lambda>
    lambda: self._connect(), lambda error: self.disconnect(error)
            ^^^^^^^^^^^^^^^
  File "/home/runner/workspace/.pythonlibs/lib/python3.11/site-packages/redis/connection.py", line 797, in _connect
    raise err
  File "/home/runner/workspace/.pythonlibs/lib/python3.11/site-packages/redis/connection.py", line 781, in _connect
    sock.connect(socket_address)
OSError: [Errno 99] Cannot assign requested address

During handling of the above exception, another exception occurred:

Traceback (most recent call last):
  File "<stdin>", line 3, in <module>
  File "/home/runner/workspace/.pythonlibs/lib/python3.11/site-packages/redis/commands/core.py", line 1219, in ping
    return self.execute_command("PING", **kwargs)
           ^^^^^^^^^^^^^^^^^^^^^^^^^^^^^^^^^^^^^^
  File "/home/runner/workspace/.pythonlibs/lib/python3.11/site-packages/redis/client.py", line 623, in execute_command
    return self._execute_command(*args, **options)
           ^^^^^^^^^^^^^^^^^^^^^^^^^^^^^^^^^^^^^^^
  File "/home/runner/workspace/.pythonlibs/lib/python3.11/site-packages/redis/client.py", line 629, in _execute_command
    conn = self.connection or pool.get_connection()
                              ^^^^^^^^^^^^^^^^^^^^^
  File "/home/runner/workspace/.pythonlibs/lib/python3.11/site-packages/redis/utils.py", line 191, in wrapper
    return func(*args, **kwargs)
           ^^^^^^^^^^^^^^^^^^^^^
  File "/home/runner/workspace/.pythonlibs/lib/python3.11/site-packages/redis/connection.py", line 1530, in get_connection
    connection.connect()
  File "/home/runner/workspace/.pythonlibs/lib/python3.11/site-packages/redis/connection.py", line 379, in connect
    self.connect_check_health(check_health=True)
  File "/home/runner/workspace/.pythonlibs/lib/python3.11/site-packages/redis/connection.py", line 391, in connect_check_health
    raise ConnectionError(self._error_message(e))
redis.exceptions.ConnectionError: Error 99 connecting to localhost:6379. Cannot assign requested address.
~/workspace$ 